{"id":"21731562065","type":"IssuesEvent","actor":{"id":8843219,"login":"dstebila","display_login":"dstebila","gravatar_id":"","url":"https://api.github.com/users/dstebila","avatar_url":"https://avatars.githubusercontent.com/u/8843219?"},"repo":{"id":162497174,"name":"open-quantum-safe/liboqs-python","url":"https://api.github.com/repos/open-quantum-safe/liboqs-python"},"payload":{"action":"closed","issue":{"url":"https://api.github.com/repos/open-quantum-safe/liboqs-python/issues/48","repository_url":"https://api.github.com/repos/open-quantum-safe/liboqs-python","labels_url":"https://api.github.com/repos/open-quantum-safe/liboqs-python/issues/48/labels{/name}","comments_url":"https://api.github.com/repos/open-quantum-safe/liboqs-python/issues/48/comments","events_url":"https://api.github.com/repos/open-quantum-safe/liboqs-python/issues/48/events","html_url":"https://github.com/open-quantum-safe/liboqs-python/issues/48","id":1228658487,"node_id":"I_kwDOCa-Cls5JO9c3","number":48,"title":"Can't pip install from docker container","user":{"login":"fredericoschardong","id":3732628,"node_id":"MDQ6VXNlcjM3MzI2Mjg=","avatar_url":"https://avatars.githubusercontent.com/u/3732628?v=4","gravatar_id":"","url":"https://api.github.com/users/fredericoschardong","html_url":"https://github.com/fredericoschardong","followers_url":"https://api.github.com/users/fredericoschardong/followers","following_url":"https://api.github.com/users/fredericoschardong/following{/other_user}","gists_url":"https://api.github.com/users/fredericoschardong/gists{/gist_id}","starred_url":"https://api.github.com/users/fredericoschardong/starred{/owner}{/repo}","subscriptions_url":"https://api.github.com/users/fredericoschardong/subscriptions","organizations_url":"https://api.github.com/users/fredericoschardong/orgs","repos_url":"https://api.github.com/users/fredericoschardong/repos","events_url":"https://api.github.com/users/fredericoschardong/events{/privacy}","received_events_url":"https://api.github.com/users/fredericoschardong/received_events","type":"User","site_admin":false},"labels":[],"state":"closed","locked":false,"assignee":null,"assignees":[],"milestone":null,"comments":5,"created_at":"2022-05-07T15:46:05Z","updated_at":"2022-05-11T12:28:18Z","closed_at":"2022-05-11T12:28:18Z","author_association":"NONE","active_lock_reason":null,"body":"Hey,\r\n\r\nIs it a bug or a feature that we can't use pip install with liboqs-pythons' docker? Or am I missing something? For instance, take the following Dockerfile as an example. If I don't use the intermediary `pre_quantum` to copy `libssl.so.1.1` and `libcrypto.so.1.1`, then I get the errors listed below. \r\n\r\n```\r\nFROM alpine:3.11 as pre_quantum\r\n\r\nRUN apk update && apk add openssl\r\n\r\nFROM openquantumsafe/python\r\n\r\nCOPY app /app\r\nWORKDIR /app\r\n\r\nUSER root\r\nRUN apk update && apk add python3-dev gcc libc-dev libffi-dev\r\n\r\nCOPY --from=pre_quantum /lib/libssl.so.1.1 /lib/libssl.so.1.1\r\nCOPY --from=pre_quantum /lib/libcrypto.so.1.1 /lib/libcrypto.so.1.1\r\n\r\nRUN pip3 install --no-cache --upgrade pip setuptools\r\nRUN pip3 install -r requirements.txt\r\n```\r\n\r\n\r\n```\r\nWARNING: Retrying (Retry(total=4, connect=None, read=None, redirect=None, status=None)) after connection broken by 'SSLError(SSLError(1, '[SSL: UNEXPECTED_MESSAGE] unexpected message (_ssl.c:1131)'))': /simple/pip/\r\nWARNING: Retrying (Retry(total=3, connect=None, read=None, redirect=None, status=None)) after connection broken by 'SSLError(SSLError(1, '[SSL: UNEXPECTED_MESSAGE] unexpected message (_ssl.c:1131)'))': /simple/pip/\r\nWARNING: Retrying (Retry(total=2, connect=None, read=None, redirect=None, status=None)) after connection broken by 'SSLError(SSLError(1, '[SSL: UNEXPECTED_MESSAGE] unexpected message (_ssl.c:1131)'))': /simple/pip/\r\nWARNING: Retrying (Retry(total=1, connect=None, read=None, redirect=None, status=None)) after connection broken by 'SSLError(SSLError(1, '[SSL: UNEXPECTED_MESSAGE] unexpected message (_ssl.c:1131)'))': /simple/pip/\r\nWARNING: Retrying (Retry(total=0, connect=None, read=None, redirect=None, status=None)) after connection broken by 'SSLError(SSLError(1, '[SSL: UNEXPECTED_MESSAGE] unexpected message (_ssl.c:1131)'))': /simple/pip/\r\nCould not fetch URL https://pypi.org/simple/pip/: There was a problem confirming the ssl certificate: HTTPSConnectionPool(host='pypi.org', port=443): Max retries exceeded with url: /simple/pip/ (Caused by SSLError(SSLError(1, '[SSL: UNEXPECTED_MESSAGE] unexpected message (_ssl.c:1131)'))) - skipping\r\n```","reactions":{"url":"https://api.github.com/repos/open-quantum-safe/liboqs-python/issues/48/reactions","total_count":0,"+1":0,"-1":0,"laugh":0,"hooray":0,"confused":0,"heart":0,"rocket":0,"eyes":0},"timeline_url":"https://api.github.com/repos/open-quantum-safe/liboqs-python/issues/48/timeline","performed_via_github_app":null}},"public":true,"created_at":"2022-05-11T12:28:19Z","org":{"id":20689385,"login":"open-quantum-safe","gravatar_id":"","url":"https://api.github.com/orgs/open-quantum-safe","avatar_url":"https://avatars.githubusercontent.com/u/20689385?"}}
